<?xml version="1.0" encoding="UTF-8"?>
<robot name="rs007l_onrobot_rg2">
  <joint name="finger_joint" type="revolute">
    <origin xyz="0. -0.017178 0.125797" rpy="-3.1415927 -0.0000001 -3.1415927"/>
    <parent link="onrobot_rg2_base_link"/>
    <child link="left_outer_knuckle"/>
    <axis xyz="1. 0. 0."/>
    <limit lower="-0.558505" upper="0.785398" effort="60000." velocity="2."/>
  </joint>
  <joint name="gripper_center_joint" type="fixed">
    <origin xyz="0. 0. 0.24" rpy="0. 0. 0."/>
    <parent link="onrobot_rg2_base_link"/>
    <child link="gripper_center"/>
  </joint>
  <joint name="joint1" type="revolute">
    <origin xyz="0. 0. 0.36" rpy="0. 1.5707964 0. "/>
    <parent link="base_link"/>
    <child link="link1"/>
    <axis xyz="1. 0. 0."/>
    <limit lower="-3.1415927" upper="3.1415927" effort="60000." velocity="6.4577182"/>
  </joint>
  <joint name="joint2" type="revolute">
    <origin xyz="0.0000001 0. 0. " rpy="0. 1.5707963 0. "/>
    <parent link="link1"/>
    <child link="link2"/>
    <axis xyz="1. 0. 0."/>
    <limit lower="-2.3561945" upper="2.3561945" effort="60000." velocity="5.4105207"/>
  </joint>
  <joint name="joint3" type="revolute">
    <origin xyz="0. -0. -0.455" rpy="-3.1415925 0. -3.1415927"/>
    <parent link="link2"/>
    <child link="link3"/>
    <axis xyz="1. 0. 0."/>
    <limit lower="-2.7401667" upper="2.7401667" effort="60000." velocity="7.1558499"/>
  </joint>
  <joint name="joint4" type="revolute">
    <origin xyz="0. -0. 0.0925" rpy="0. -1.5707963 0. "/>
    <parent link="link3"/>
    <child link="link4"/>
    <axis xyz="1. 0. 0."/>
    <limit lower="-3.4906582" upper="3.4906582" effort="60000." velocity="9.5993109"/>
  </joint>
  <joint name="joint5" type="revolute">
    <origin xyz="0.3825 0. -0. " rpy="-1.8098018 1.5707961 -1.8098018"/>
    <parent link="link4"/>
    <child link="link5"/>
    <axis xyz="1. 0. 0."/>
    <limit lower="-2.1816614" upper="2.1816614" effort="60000." velocity="9.5993109"/>
  </joint>
  <joint name="joint6" type="revolute">
    <origin xyz="-0. -0. 0.0779998" rpy="2.3561945 -1.5707963 -2.3561943"/>
    <parent link="link5"/>
    <child link="link6"/>
    <axis xyz="1. 0. 0."/>
    <limit lower="-6.2831853" upper="6.2831853" effort="60000." velocity="17.4532925"/>
  </joint>
  <joint name="left_inner_finger_joint" type="revolute">
    <origin xyz="0. -0.039592 -0.0381769" rpy="-3.1415927 0.0000001 -3.1415927"/>
    <parent link="left_outer_knuckle"/>
    <child link="left_inner_finger"/>
    <axis xyz="1. 0. 0."/>
    <limit lower="-0.872665" upper="0.872665" effort="60000." velocity="2."/>
  </joint>
  <joint name="left_inner_knuckle_joint" type="revolute">
    <origin xyz="0. -0.007678 0.142297" rpy="0. 0. 0."/>
    <parent link="onrobot_rg2_base_link"/>
    <child link="left_inner_knuckle"/>
    <axis xyz="1. 0. 0."/>
    <limit lower="-0.558505" upper="0.785398" effort="60000." velocity="2."/>
  </joint>
  <joint name="right_inner_finger_joint" type="revolute">
    <origin xyz="0. -0.039592 0.0381769" rpy="0. 0. 0.0000005"/>
    <parent link="right_outer_knuckle"/>
    <child link="right_inner_finger"/>
    <axis xyz="1. 0. 0."/>
    <limit lower="-0.872665" upper="0.872665" effort="60000." velocity="2."/>
  </joint>
  <joint name="right_inner_knuckle_joint" type="revolute">
    <origin xyz="0. 0.007678 0.142297" rpy="0. 0. 3.1415925"/>
    <parent link="onrobot_rg2_base_link"/>
    <child link="right_inner_knuckle"/>
    <axis xyz="1. 0. 0."/>
    <limit lower="-0.558505" upper="0.785398" effort="60000." velocity="2."/>
  </joint>
  <joint name="right_outer_knuckle_joint" type="revolute">
    <origin xyz="0. 0.017178 0.125797" rpy="0. 0. -3.1415925"/>
    <parent link="onrobot_rg2_base_link"/>
    <child link="right_outer_knuckle"/>
    <axis xyz="1. 0. 0."/>
    <limit lower="-0.558505" upper="0.785398" effort="60000." velocity="2."/>
  </joint>
  <joint name="root_joint" type="fixed">
    <origin xyz="0. 0. 0." rpy="0. 0. 0."/>
    <parent link="World"/>
    <child link="world"/>
  </joint>
  <joint name="rs007l2rg2" type="fixed">
    <origin xyz="-0.0000001 -0. -0. " rpy="-2.1431708 1.5707961 -2.1431708"/>
    <parent link="link6"/>
    <child link="onrobot_rg2_base_link"/>
  </joint>
  <joint name="world2base" type="fixed">
    <origin xyz="0. 0. 0." rpy="0. 0. -1.5707964"/>
    <parent link="world"/>
    <child link="base_link"/>
  </joint>
  <link name="World"/>
  <link name="base_link">
    <inertial>
      <origin xyz="0. 0. 0." rpy="0. 0. 0."/>
      <mass value="11."/>
      <inertia ixx="0.001" ixy="0." ixz="0." iyy="0.001" iyz="0." izz="0.001"/>
    </inertial>
    <visual>
      <origin xyz="0. 0. 0." rpy="0. 0. -0."/>
      <geometry>
        <mesh filename="file:///home/leo/ws_isaacsim/kawasaki/src/robots/rs007l/meshes/base_link_visuals.obj" scale="1. 1. 1."/>
      </geometry>
    </visual>
    <visual>
      <origin xyz="0. 0. 0." rpy="0. 0. -0."/>
      <geometry>
        <mesh filename="file:///home/leo/ws_isaacsim/kawasaki/src/robots/rs007l/meshes/base_link_collisions.obj" scale="1. 1. 1."/>
      </geometry>
    </visual>
    <collision>
      <origin xyz="0. 0. 0." rpy="0. 0. -0."/>
      <geometry>
        <mesh filename="file:///home/leo/ws_isaacsim/kawasaki/src/robots/rs007l/meshes/base_link_collisions.obj" scale="1. 1. 1."/>
      </geometry>
    </collision>
  </link>
  <link name="gripper_center"/>
  <link name="left_inner_finger">
    <inertial>
      <origin xyz="0. 0. 0." rpy="0. 0. 0."/>
      <mass value="0.05"/>
      <inertia ixx="0.001" ixy="0." ixz="0." iyy="0.001" iyz="0." izz="0.001"/>
    </inertial>
    <visual>
      <origin xyz="0. 0. 0." rpy="0. 0. 0."/>
      <geometry>
        <mesh filename="file:///home/leo/ws_isaacsim/kawasaki/src/robots/rs007l/meshes/left_inner_finger_visuals.obj" scale="1. 1. 1."/>
      </geometry>
    </visual>
    <visual>
      <origin xyz="0. 0. 0." rpy="0. 0. 0."/>
      <geometry>
        <mesh filename="file:///home/leo/ws_isaacsim/kawasaki/src/robots/rs007l/meshes/left_inner_finger_collisions.obj" scale="1. 1. 1."/>
      </geometry>
    </visual>
    <collision>
      <origin xyz="0. 0. 0." rpy="0. 0. 0."/>
      <geometry>
        <mesh filename="file:///home/leo/ws_isaacsim/kawasaki/src/robots/rs007l/meshes/left_inner_finger_collisions.obj" scale="1. 1. 1."/>
      </geometry>
    </collision>
  </link>
  <link name="left_inner_knuckle">
    <inertial>
      <origin xyz="0. 0. 0." rpy="0. 0. 0."/>
      <mass value="0.05"/>
      <inertia ixx="0.001" ixy="0." ixz="0." iyy="0.001" iyz="0." izz="0.001"/>
    </inertial>
    <visual>
      <origin xyz="0. 0. -0.0000001" rpy="0. 0. 0."/>
      <geometry>
        <mesh filename="file:///home/leo/ws_isaacsim/kawasaki/src/robots/rs007l/meshes/left_inner_knuckle_visuals.obj" scale="1. 1. 1."/>
      </geometry>
    </visual>
    <visual>
      <origin xyz="0. 0. -0.0000001" rpy="0. 0. 0."/>
      <geometry>
        <mesh filename="file:///home/leo/ws_isaacsim/kawasaki/src/robots/rs007l/meshes/left_inner_knuckle_collisions.obj" scale="1. 1. 1."/>
      </geometry>
    </visual>
    <collision>
      <origin xyz="0. 0. -0.0000001" rpy="0. 0. 0."/>
      <geometry>
        <mesh filename="file:///home/leo/ws_isaacsim/kawasaki/src/robots/rs007l/meshes/left_inner_knuckle_collisions.obj" scale="1. 1. 1."/>
      </geometry>
    </collision>
  </link>
  <link name="left_outer_knuckle">
    <inertial>
      <origin xyz="0. 0. 0." rpy="0. 0. 0."/>
      <mass value="0.05"/>
      <inertia ixx="0.001" ixy="0." ixz="0." iyy="0.001" iyz="0." izz="0.001"/>
    </inertial>
    <visual>
      <origin xyz="-0. 0. 0.0000001" rpy="-3.1415927 0.0000001 -3.1415927"/>
      <geometry>
        <mesh filename="file:///home/leo/ws_isaacsim/kawasaki/src/robots/rs007l/meshes/left_outer_knuckle_visuals.obj" scale="1. 1. 1."/>
      </geometry>
    </visual>
    <visual>
      <origin xyz="-0. 0. 0.0000001" rpy="-3.1415927 0.0000001 -3.1415927"/>
      <geometry>
        <mesh filename="file:///home/leo/ws_isaacsim/kawasaki/src/robots/rs007l/meshes/left_outer_knuckle_collisions.obj" scale="1. 1. 1."/>
      </geometry>
    </visual>
    <collision>
      <origin xyz="-0. 0. 0.0000001" rpy="-3.1415927 0.0000001 -3.1415927"/>
      <geometry>
        <mesh filename="file:///home/leo/ws_isaacsim/kawasaki/src/robots/rs007l/meshes/left_outer_knuckle_collisions.obj" scale="1. 1. 1."/>
      </geometry>
    </collision>
  </link>
  <link name="link1">
    <inertial>
      <origin xyz="0. 0. 0." rpy="0. 0. 0."/>
      <mass value="8.1879997"/>
      <inertia ixx="0.001" ixy="0." ixz="0." iyy="0.001" iyz="0." izz="0.001"/>
    </inertial>
    <visual>
      <origin xyz="0.0000001 0. 0. " rpy="0. -1.5707963 0. "/>
      <geometry>
        <mesh filename="file:///home/leo/ws_isaacsim/kawasaki/src/robots/rs007l/meshes/link1_visuals.obj" scale="1. 1. 1."/>
      </geometry>
    </visual>
    <visual>
      <origin xyz="0.0000001 0. 0. " rpy="0. -1.5707963 0. "/>
      <geometry>
        <mesh filename="file:///home/leo/ws_isaacsim/kawasaki/src/robots/rs007l/meshes/link1_collisions.obj" scale="1. 1. 1."/>
      </geometry>
    </visual>
    <collision>
      <origin xyz="0.0000001 0. 0. " rpy="0. -1.5707963 0. "/>
      <geometry>
        <mesh filename="file:///home/leo/ws_isaacsim/kawasaki/src/robots/rs007l/meshes/link1_collisions.obj" scale="1. 1. 1."/>
      </geometry>
    </collision>
  </link>
  <link name="link2">
    <inertial>
      <origin xyz="0. 0. 0." rpy="0. 0. 0."/>
      <mass value="6.8260002"/>
      <inertia ixx="0.001" ixy="0." ixz="0." iyy="0.001" iyz="0." izz="0.001"/>
    </inertial>
    <visual>
      <origin xyz="0. 0. 0." rpy="-3.1415925 0. -3.1415927"/>
      <geometry>
        <mesh filename="file:///home/leo/ws_isaacsim/kawasaki/src/robots/rs007l/meshes/link2_visuals.obj" scale="1. 1. 1."/>
      </geometry>
    </visual>
    <visual>
      <origin xyz="0. 0. 0." rpy="-3.1415925 0. -3.1415927"/>
      <geometry>
        <mesh filename="file:///home/leo/ws_isaacsim/kawasaki/src/robots/rs007l/meshes/link2_collisions.obj" scale="1. 1. 1."/>
      </geometry>
    </visual>
    <collision>
      <origin xyz="0. 0. 0." rpy="-3.1415925 0. -3.1415927"/>
      <geometry>
        <mesh filename="file:///home/leo/ws_isaacsim/kawasaki/src/robots/rs007l/meshes/link2_collisions.obj" scale="1. 1. 1."/>
      </geometry>
    </collision>
  </link>
  <link name="link3">
    <inertial>
      <origin xyz="0. 0. 0." rpy="0. 0. 0."/>
      <mass value="5.2360001"/>
      <inertia ixx="0.001" ixy="0." ixz="0." iyy="0.001" iyz="0." izz="0.001"/>
    </inertial>
    <visual>
      <origin xyz="0. -0. -0." rpy="0. 0. 0."/>
      <geometry>
        <mesh filename="file:///home/leo/ws_isaacsim/kawasaki/src/robots/rs007l/meshes/link3_visuals.obj" scale="1. 1. 1."/>
      </geometry>
    </visual>
    <visual>
      <origin xyz="0. -0. -0." rpy="0. 0. 0."/>
      <geometry>
        <mesh filename="file:///home/leo/ws_isaacsim/kawasaki/src/robots/rs007l/meshes/link3_collisions.obj" scale="1. 1. 1."/>
      </geometry>
    </visual>
    <collision>
      <origin xyz="0. -0. -0." rpy="0. 0. 0."/>
      <geometry>
        <mesh filename="file:///home/leo/ws_isaacsim/kawasaki/src/robots/rs007l/meshes/link3_collisions.obj" scale="1. 1. 1."/>
      </geometry>
    </collision>
  </link>
  <link name="link4">
    <inertial>
      <origin xyz="0. 0. 0." rpy="0. 0. 0."/>
      <mass value="5.066"/>
      <inertia ixx="0.001" ixy="0." ixz="0." iyy="0.001" iyz="0." izz="0.001"/>
    </inertial>
    <visual>
      <origin xyz="0.3825 0. -0. " rpy="-1.8098018 1.5707961 -1.8098018"/>
      <geometry>
        <mesh filename="file:///home/leo/ws_isaacsim/kawasaki/src/robots/rs007l/meshes/link4_visuals.obj" scale="1. 1. 1."/>
      </geometry>
    </visual>
    <visual>
      <origin xyz="0.3825 0. -0. " rpy="-1.8098018 1.5707961 -1.8098018"/>
      <geometry>
        <mesh filename="file:///home/leo/ws_isaacsim/kawasaki/src/robots/rs007l/meshes/link4_collisions.obj" scale="1. 1. 1."/>
      </geometry>
    </visual>
    <collision>
      <origin xyz="0.3825 0. -0. " rpy="-1.8098018 1.5707961 -1.8098018"/>
      <geometry>
        <mesh filename="file:///home/leo/ws_isaacsim/kawasaki/src/robots/rs007l/meshes/link4_collisions.obj" scale="1. 1. 1."/>
      </geometry>
    </collision>
  </link>
  <link name="link5">
    <inertial>
      <origin xyz="0. 0. 0." rpy="0. 0. 0."/>
      <mass value="1.625"/>
      <inertia ixx="0.001" ixy="0." ixz="0." iyy="0.001" iyz="0." izz="0.001"/>
    </inertial>
    <visual>
      <origin xyz="0. 0. -0.0000002" rpy="0.0000001 -0. 0.0000001"/>
      <geometry>
        <mesh filename="file:///home/leo/ws_isaacsim/kawasaki/src/robots/rs007l/meshes/link5_visuals.obj" scale="1. 1. 1."/>
      </geometry>
    </visual>
    <visual>
      <origin xyz="0. 0. -0.0000002" rpy="0.0000001 -0. 0.0000001"/>
      <geometry>
        <mesh filename="file:///home/leo/ws_isaacsim/kawasaki/src/robots/rs007l/meshes/link5_collisions.obj" scale="1. 1. 1."/>
      </geometry>
    </visual>
    <collision>
      <origin xyz="0. 0. -0.0000002" rpy="0.0000001 -0. 0.0000001"/>
      <geometry>
        <mesh filename="file:///home/leo/ws_isaacsim/kawasaki/src/robots/rs007l/meshes/link5_collisions.obj" scale="1. 1. 1."/>
      </geometry>
    </collision>
  </link>
  <link name="link6">
    <inertial>
      <origin xyz="0. 0. 0." rpy="0. 0. 0."/>
      <mass value="0.625"/>
      <inertia ixx="0.001" ixy="0." ixz="0." iyy="0.001" iyz="0." izz="0.001"/>
    </inertial>
    <visual>
      <origin xyz="-0.0000001 -0. -0. " rpy="-2.1431708 1.5707961 -2.1431708"/>
      <geometry>
        <mesh filename="file:///home/leo/ws_isaacsim/kawasaki/src/robots/rs007l/meshes/link6_visuals.obj" scale="1. 1. 1."/>
      </geometry>
    </visual>
    <visual>
      <origin xyz="-0.0000001 -0. -0. " rpy="-2.1431708 1.5707961 -2.1431708"/>
      <geometry>
        <mesh filename="file:///home/leo/ws_isaacsim/kawasaki/src/robots/rs007l/meshes/link6_collisions.obj" scale="1. 1. 1."/>
      </geometry>
    </visual>
    <collision>
      <origin xyz="-0.0000001 -0. -0. " rpy="-2.1431708 1.5707961 -2.1431708"/>
      <geometry>
        <mesh filename="file:///home/leo/ws_isaacsim/kawasaki/src/robots/rs007l/meshes/link6_collisions.obj" scale="1. 1. 1."/>
      </geometry>
    </collision>
  </link>
  <link name="onrobot_rg2_base_link">
    <inertial>
      <origin xyz="0. 0. 0." rpy="0. 0. 0."/>
      <mass value="0.7"/>
      <inertia ixx="0.001" ixy="0." ixz="0." iyy="0.001" iyz="0." izz="0.001"/>
    </inertial>
    <visual>
      <origin xyz="0. 0. 0." rpy="0. 0. 0."/>
      <geometry>
        <mesh filename="file:///home/leo/ws_isaacsim/kawasaki/src/robots/rs007l/meshes/onrobot_rg2_base_link_visuals.obj" scale="1. 1. 1."/>
      </geometry>
    </visual>
    <visual>
      <origin xyz="0. 0. 0." rpy="0. 0. 0."/>
      <geometry>
        <mesh filename="file:///home/leo/ws_isaacsim/kawasaki/src/robots/rs007l/meshes/onrobot_rg2_base_link_collisions.obj" scale="1. 1. 1."/>
      </geometry>
    </visual>
    <collision>
      <origin xyz="0. 0. 0." rpy="0. 0. 0."/>
      <geometry>
        <mesh filename="file:///home/leo/ws_isaacsim/kawasaki/src/robots/rs007l/meshes/onrobot_rg2_base_link_collisions.obj" scale="1. 1. 1."/>
      </geometry>
    </collision>
  </link>
  <link name="right_inner_finger">
    <inertial>
      <origin xyz="0. 0. 0." rpy="0. 0. 0."/>
      <mass value="0.05"/>
      <inertia ixx="0.001" ixy="0." ixz="0." iyy="0.001" iyz="0." izz="0.001"/>
    </inertial>
    <visual>
      <origin xyz="-0. 0. 0." rpy="0. 0. 0."/>
      <geometry>
        <mesh filename="file:///home/leo/ws_isaacsim/kawasaki/src/robots/rs007l/meshes/right_inner_finger_visuals.obj" scale="1. 1. 1."/>
      </geometry>
    </visual>
    <visual>
      <origin xyz="-0. 0. 0." rpy="0. 0. 0."/>
      <geometry>
        <mesh filename="file:///home/leo/ws_isaacsim/kawasaki/src/robots/rs007l/meshes/right_inner_finger_collisions.obj" scale="1. 1. 1."/>
      </geometry>
    </visual>
    <collision>
      <origin xyz="-0. 0. 0." rpy="0. 0. 0."/>
      <geometry>
        <mesh filename="file:///home/leo/ws_isaacsim/kawasaki/src/robots/rs007l/meshes/right_inner_finger_collisions.obj" scale="1. 1. 1."/>
      </geometry>
    </collision>
  </link>
  <link name="right_inner_knuckle">
    <inertial>
      <origin xyz="0. 0. 0." rpy="0. 0. 0."/>
      <mass value="0.05"/>
      <inertia ixx="0.001" ixy="0." ixz="0." iyy="0.001" iyz="0." izz="0.001"/>
    </inertial>
    <visual>
      <origin xyz="0. 0. -0.0000001" rpy="0. 0. 0.0000003"/>
      <geometry>
        <mesh filename="file:///home/leo/ws_isaacsim/kawasaki/src/robots/rs007l/meshes/right_inner_knuckle_visuals.obj" scale="1. 1. 1."/>
      </geometry>
    </visual>
    <visual>
      <origin xyz="0. 0. -0.0000001" rpy="0. 0. 0.0000003"/>
      <geometry>
        <mesh filename="file:///home/leo/ws_isaacsim/kawasaki/src/robots/rs007l/meshes/right_inner_knuckle_collisions.obj" scale="1. 1. 1."/>
      </geometry>
    </visual>
    <collision>
      <origin xyz="0. 0. -0.0000001" rpy="0. 0. 0.0000003"/>
      <geometry>
        <mesh filename="file:///home/leo/ws_isaacsim/kawasaki/src/robots/rs007l/meshes/right_inner_knuckle_collisions.obj" scale="1. 1. 1."/>
      </geometry>
    </collision>
  </link>
  <link name="right_outer_knuckle">
    <inertial>
      <origin xyz="0. 0. 0." rpy="0. 0. 0."/>
      <mass value="0.05"/>
      <inertia ixx="0.001" ixy="0." ixz="0." iyy="0.001" iyz="0." izz="0.001"/>
    </inertial>
    <visual>
      <origin xyz="0. 0. -0.0000001" rpy="0. 0. 0.0000005"/>
      <geometry>
        <mesh filename="file:///home/leo/ws_isaacsim/kawasaki/src/robots/rs007l/meshes/right_outer_knuckle_visuals.obj" scale="1. 1. 1."/>
      </geometry>
    </visual>
    <visual>
      <origin xyz="0. 0. -0.0000001" rpy="0. 0. 0.0000005"/>
      <geometry>
        <mesh filename="file:///home/leo/ws_isaacsim/kawasaki/src/robots/rs007l/meshes/right_outer_knuckle_collisions.obj" scale="1. 1. 1."/>
      </geometry>
    </visual>
    <collision>
      <origin xyz="0. 0. -0.0000001" rpy="0. 0. 0.0000005"/>
      <geometry>
        <mesh filename="file:///home/leo/ws_isaacsim/kawasaki/src/robots/rs007l/meshes/right_outer_knuckle_collisions.obj" scale="1. 1. 1."/>
      </geometry>
    </collision>
  </link>
  <link name="world"/>
</robot>
